<?xml version="1.0"?>
<robot name="lidar_car" xmlns:xacro="http://www.ros.org/wiki/xacro">

  <!-- ===== MATERIALS ===== -->
  <material name="blue">
    <color rgba="0.0 0.0 0.8 1.0"/>
  </material>
  <material name="black">
    <color rgba="0.0 0.0 0.0 1.0"/>
  </material>
  <material name="red">
    <color rgba="0.8 0.0 0.0 1.0"/>
  </material>

  <!-- ===== BASE LINK ===== -->
  <link name="base_footprint"/>

  <joint name="base_joint" type="fixed">
    <parent link="base_footprint"/>
    <child  link="base_link"/>
    <origin xyz="0 0 0.1" rpy="0 0 0"/>
  </joint>

  <link name="base_link">
    <visual>
      <geometry><box size="0.4 0.2 0.1"/></geometry>
      <material name="blue"/>
    </visual>
    <collision>
      <geometry><box size="0.4 0.2 0.1"/></geometry>
    </collision>
    <inertial>
      <mass value="2.0"/>
      <inertia ixx="0.0083" ixy="0" ixz="0"
               iyy="0.0333" iyz="0" izz="0.0375"/>
    </inertial>
  </link>

  <!-- ===== LEFT WHEEL ===== -->
  <joint name="left_wheel_joint" type="continuous">
    <parent link="base_link"/>
    <child  link="left_wheel"/>
    <origin xyz="0 0.13 -0.05" rpy="-1.5708 0 0"/>
    <axis xyz="0 0 1"/>
  </joint>

  <link name="left_wheel">
    <visual>
      <geometry><cylinder length="0.05" radius="0.05"/></geometry>
      <material name="black"/>
    </visual>
    <collision>
      <geometry><cylinder length="0.05" radius="0.05"/></geometry>
    </collision>
    <inertial>
      <mass value="0.5"/>
      <inertia ixx="0.000317" ixy="0" ixz="0"
               iyy="0.000317" iyz="0" izz="0.000625"/>
    </inertial>
  </link>

  <!-- ===== RIGHT WHEEL ===== -->
  <joint name="right_wheel_joint" type="continuous">
    <parent link="base_link"/>
    <child  link="right_wheel"/>
    <origin xyz="0 -0.13 -0.05" rpy="-1.5708 0 0"/>
    <axis xyz="0 0 1"/>
  </joint>

  <link name="right_wheel">
    <visual>
      <geometry><cylinder length="0.05" radius="0.05"/></geometry>
      <material name="black"/>
    </visual>
    <collision>
      <geometry><cylinder length="0.05" radius="0.05"/></geometry>
    </collision>
    <inertial>
      <mass value="0.5"/>
      <inertia ixx="0.000317" ixy="0" ixz="0"
               iyy="0.000317" iyz="0" izz="0.000625"/>
    </inertial>
  </link>

  <!-- ===== CASTER WHEEL ===== -->
  <joint name="caster_joint" type="fixed">
    <parent link="base_link"/>
    <child  link="caster_wheel"/>
    <origin xyz="-0.15 0 -0.05" rpy="0 0 0"/>
  </joint>

  <link name="caster_wheel">
    <visual>
      <geometry><sphere radius="0.05"/></geometry>
      <material name="black"/>
    </visual>
    <collision>
      <geometry><sphere radius="0.05"/></geometry>
    </collision>
    <inertial>
      <mass value="0.3"/>
      <inertia ixx="0.0003" ixy="0" ixz="0"
               iyy="0.0003" iyz="0" izz="0.0003"/>
    </inertial>
  </link>

  <!-- ===== LIDAR MOUNT ===== -->
  <joint name="lidar_joint" type="fixed">
    <parent link="base_link"/>
    <child  link="lidar_link"/>
    <origin xyz="0.15 0 0.08" rpy="0 0 0"/>
  </joint>

  <link name="lidar_link">
    <visual>
      <geometry><cylinder length="0.04" radius="0.03"/></geometry>
      <material name="red"/>
    </visual>
    <collision>
      <geometry><cylinder length="0.04" radius="0.03"/></geometry>
    </collision>
    <inertial>
      <mass value="0.1"/>
      <inertia ixx="0.0001" ixy="0" ixz="0"
               iyy="0.0001" iyz="0" izz="0.0001"/>
    </inertial>
  </link>

  <!-- ===== GAZEBO PLUGINS ===== -->

  <!-- Differential Drive -->
  <gazebo>
    <plugin name="diff_drive" filename="libgazebo_ros_diff_drive.so">
      <left_joint>left_wheel_joint</left_joint>
      <right_joint>right_wheel_joint</right_joint>
      <wheel_separation>0.26</wheel_separation>
      <wheel_diameter>0.1</wheel_diameter>
      <max_wheel_torque>20</max_wheel_torque>
      <max_wheel_acceleration>1.0</max_wheel_acceleration>
      <command_topic>cmd_vel</command_topic>
      <publish_odom>true</publish_odom>
      <publish_odom_tf>true</publish_odom_tf>
      <publish_wheel_tf>true</publish_wheel_tf>
      <odometry_frame>odom</odometry_frame>
      <robot_base_frame>base_footprint</robot_base_frame>
    </plugin>
  </gazebo>

  <!-- LiDAR Sensor -->
  <gazebo reference="lidar_link">
    <sensor name="lidar" type="ray">
      <always_on>true</always_on>
      <visualize>true</visualize>
      <update_rate>10</update_rate>
      <ray>
        <scan>
          <horizontal>
            <samples>360</samples>
            <resolution>1</resolution>
            <min_angle>-3.14159</min_angle>
            <max_angle>3.14159</max_angle>
          </horizontal>
        </scan>
        <range>
          <min>0.12</min>
          <max>10.0</max>
          <resolution>0.01</resolution>
        </range>
        <noise>
          <type>gaussian</type>
          <mean>0.0</mean>
          <stddev>0.01</stddev>
        </noise>
      </ray>
      <plugin name="lidar_plugin" filename="libgazebo_ros_ray_sensor.so">
        <ros>
          <remapping>~/out:=scan</remapping>
        </ros>
        <output_type>sensor_msgs/LaserScan</output_type>
        <frame_name>lidar_link</frame_name>
      </plugin>
    </sensor>
  </gazebo>

  <!-- Caster friction = 0 -->
  <gazebo reference="caster_wheel">
    <mu1>0.0</mu1>
    <mu2>0.0</mu2>
  </gazebo>

</robot>